#VRML_SIM R2023b utf8

EXTERNPROTO "https://raw.githubusercontent.com/cyberbotics/webots/R2023b/projects/objects/backgrounds/protos/TexturedBackground.proto"
EXTERNPROTO "https://raw.githubusercontent.com/cyberbotics/webots/R2023b/projects/objects/backgrounds/protos/TexturedBackgroundLight.proto"
EXTERNPROTO "https://raw.githubusercontent.com/cyberbotics/webots/R2023b/projects/objects/factory/containers/protos/WoodenBox.proto"
EXTERNPROTO "https://raw.githubusercontent.com/cyberbotics/webots/R2023b/projects/objects/floors/protos/Floor.proto"
EXTERNPROTO "https://raw.githubusercontent.com/cyberbotics/webots/R2023b/projects/appearances/protos/OldSteel.proto"
EXTERNPROTO "../protos/FourWheelsRobot.proto"

WorldInfo {
  basicTimeStep 16
  physicsDisableTime 0
}
Viewpoint {
  orientation 0.4620889762723887 0.013896339929929967 -0.8867246865538861 3.088266464865849
  position 0.9192138630154864 0.22962334114334365 1.2474146137963726
  followType "None"
}
TexturedBackground {
}
TexturedBackgroundLight {
}
Floor {
  size 1 1
}
WoodenBox {
  translation 0.186892 -0.252433 0.05
  size 0.1 0.1 0.1
}
WoodenBox {
  translation -0.0580565 -0.321112 0.05
  name "wooden box(1)"
  size 0.1 0.1 0.1
  mass 0.2
}
WoodenBox {
  translation -0.316209 -0.168953 0.05
  name "wooden box(2)"
  size 0.1 0.1 0.1
  mass 0.2
}
DEF WALL_1 Solid {
  translation 0 0.49 0.05
  children [
    DEF WALL_SHAPE Shape {
      appearance OldSteel {
      }
      geometry Box {
        size 1 0.025 0.1
      }
    }
  ]
  name "solid(1)"
  boundingObject USE WALL_SHAPE
}
DEF WALL_2 Solid {
  translation 0 -0.49 0.05
  children [
    USE WALL_SHAPE
  ]
  name "solid(2)"
  boundingObject USE WALL_SHAPE
}
DEF WALL_3 Solid {
  translation -0.51 -5.20006e-07 0.05
  rotation 0 0 1 -1.5707953071795862
  children [
    USE WALL_SHAPE
  ]
  name "solid(3)"
  boundingObject USE WALL_SHAPE
}
DEF WALL_4 Solid {
  translation 0.5 1.83658e-06 0.05
  rotation 0 0 1 1.5708
  children [
    USE WALL_SHAPE
  ]
  name "solid(4)"
  boundingObject USE WALL_SHAPE
}
Robot {
  translation -0.31 0.25 0.032
  rotation 0 0 1 3.14159
  children [
    DEF BODY Shape {
      appearance PBRAppearance {
        baseColor 0.666667 0 0
        metalness 0
      }
      geometry Box {
        size 0.2 0.1 0.05
      }
    }
    DistanceSensor {
      translation -0.1 -0.025 0.01
      rotation 0 0 -1 2.35313
      children [
        Shape {
          appearance PBRAppearance {
            baseColor 0 0.333333 1
            metalness 0
          }
          geometry Box {
            size 0.01 0.01 0.01
          }
        }
      ]
      name "ds_left"
      boundingObject Box {
        size 0.01 0.01 0.01
      }
    }
    DistanceSensor {
      translation -0.1 0.025 0.01
      rotation 0 0 1 2.35313
      children [
        Shape {
          appearance PBRAppearance {
            baseColor 0 0.333333 1
            metalness 0
          }
          geometry Box {
            size 0.01 0.01 0.01
          }
        }
      ]
      name "ds_right"
      boundingObject Box {
        size 0.01 0.01 0.01
      }
    }
    HingeJoint {
      jointParameters HingeJointParameters {
        axis 0 1 0
        anchor -0.05 -0.06 0.0084636
      }
      device [
        RotationalMotor {
          name "wheel1"
        }
      ]
      endPoint DEF WHEEL1 Solid {
        translation -0.05 -0.06 0.008465310000000002
        rotation 3.39051142717338e-09 0.7071052811843602 0.707108281185553 3.14159
        children [
          DEF WHEEL Shape {
            appearance PBRAppearance {
              baseColor 0 0.666667 0
              metalness 0
            }
            geometry Cylinder {
              height 0.02
              radius 0.04
            }
          }
        ]
        name "solid(1)"
        boundingObject USE WHEEL
        physics DEF WHEEL_PH Physics {
        }
      }
    }
    HingeJoint {
      jointParameters HingeJointParameters {
        axis 0 1 0
        anchor -0.05 0.06 0.0084636
      }
      device [
        RotationalMotor {
          name "wheel2"
        }
      ]
      endPoint DEF WHEEL1 Solid {
        translation -0.05 0.06 0.008464189999999998
        rotation 3.3905113716622283e-09 0.7071052811843599 0.7071082811855532 3.14159
        children [
          DEF WHEEL Shape {
            appearance PBRAppearance {
              baseColor 0 0.666667 0
              metalness 0
            }
            geometry Cylinder {
              height 0.02
              radius 0.04
            }
          }
        ]
        name "solid(4)"
        boundingObject USE WHEEL
        physics DEF WHEEL_PH Physics {
        }
      }
    }
    HingeJoint {
      jointParameters HingeJointParameters {
        axis 0 1 0
        anchor 0.05 -0.06 0.0084636
      }
      device [
        RotationalMotor {
          name "wheel3"
        }
      ]
      endPoint DEF WHEEL1 Solid {
        translation 0.05 -0.06 0.008464189999999998
        rotation 3.3905113716622283e-09 0.70710528118436 0.7071082811855531 3.14159
        children [
          DEF WHEEL Shape {
            appearance PBRAppearance {
              baseColor 0 0.666667 0
              metalness 0
            }
            geometry Cylinder {
              height 0.02
              radius 0.04
            }
          }
        ]
        name "solid(3)"
        boundingObject USE WHEEL
        physics DEF WHEEL_PH Physics {
        }
      }
    }
    HingeJoint {
      jointParameters HingeJointParameters {
        axis 0 1 0
        anchor 0.05 0.06 0.0084636
      }
      device [
        RotationalMotor {
          name "wheel4"
        }
      ]
      endPoint DEF WHEEL1 Solid {
        translation 0.05 0.06 0.008465310000000002
        rotation 3.3905113716622283e-09 0.7071052811843601 0.707108281185553 3.14159
        children [
          DEF WHEEL Shape {
            appearance PBRAppearance {
              baseColor 0 0.666667 0
              metalness 0
            }
            geometry Cylinder {
              height 0.02
              radius 0.04
            }
          }
        ]
        name "solid(2)"
        boundingObject USE WHEEL
        physics DEF WHEEL_PH Physics {
        }
      }
    }
  ]
  boundingObject USE BODY
  physics Physics {
    density -1
    mass 1
  }
  controller "four_wheeled_collision_avoidance"
  window "4_wheel_robot_window"
}
FourWheelsRobot {
  translation 0.32 0.25 0.032
}
